Workbook

Sheet Chamados no Jira
A1: Data Criada | B1: Pedido | C1: After Sales | D1: Nfe | E1: Finalizado | F1: Data Atual | G1: Dias em Atraso | H1: SLA
A2: 45882 | B2: MGZ-LU-1453770462996658 (1484243) | C2: AFS-33241 | D2: 001001884-4 | E2: Resolvido | F2: =TODAY() -> 46035 | G2: =NETWORKDAYS.INTL(A2,F2,1,'Feriado 2026'!$A$2:$A$14) -> 108 | H2: =IF(G2<=2,"Dentro do SLA","Fora do SLA") -> Fora do SLA
A3: 45882 | B3: WBC-A001239641937 (1493008) | C3: AFS-33235 | D3: 001009597-4 | E3: Resolvido | F3: =TODAY() -> 46035 | G3: =NETWORKDAYS.INTL(A3,F3,1,'Feriado 2026'!$A$2:$A$14) -> 108 | H3: =IF(G3<=2,"Dentro do SLA","Fora do SLA") -> Fora do SLA
A4: 45882 | B4: MGZ-LU-1455970464077277 (1494748) | C4: AFS-33233 | D4: 001010494-4 | E4: Resolvido | F4: =TODAY() -> 46035 | G4: =NETWORKDAYS.INTL(A4,F4,1,'Feriado 2026'!$A$2:$A$14) -> 108 | H4: =IF(G4<=2,"Dentro do SLA","Fora do SLA") -> Fora do SLA
A5: 45882 | B5: MZN-702-6023172-5077048 (1494718) | C5: AFS-33228 | D5: 001010578-4 | E5: Resolvido | F5: =TODAY() -> 46035 | G5: =NETWORKDAYS.INTL(A5,F5,1,'Feriado 2026'!$A$2:$A$14) -> 108 | H5: =IF(G5<=2,"Dentro do SLA","Fora do SLA") -> Fora do SLA
A6: 45882 | B6: MGZ-LU-1454570463352116 (1488895) | C6: AFS-33224 | D6: 001006166-4 | E6: Resolvido | F6: =TODAY() -> 46035 | G6: =NETWORKDAYS.INTL(A6,F6,1,'Feriado 2026'!$A$2:$A$14) -> 108 | H6: =IF(G6<=2,"Dentro do SLA","Fora do SLA") -> Fora do SLA
A7: 45882 | B7: MLC-45251905722 (1501073) | C7: AFS-33247 | D7: 001014424-4 | E7: Em aberto | F7: =TODAY() -> 46035 | G7: =NETWORKDAYS.INTL(A7,F7,1,'Feriado 2026'!$A$2:$A$14) -> 108 | H7: =IF(G7<=2,"Dentro do SLA","Fora do SLA") -> Fora do SLA
A8: 45882 | B8: MGZ-LU-1444770458496723 (1429703) | C8: AFS-33244 | D8: 000968403-4 | E8: Em aberto | F8: =TODAY() -> 46035 | G8: =NETWORKDAYS.INTL(A8,F8,1,'Feriado 2026'!$A$2:$A$14) -> 108 | H8: =IF(G8<=2,"Dentro do SLA","Fora do SLA") -> Fora do SLA
A9: 45882 | B9: VVJ-47496815401 (1481639) | C9: AFS-33135 | D9: 001000706-4 | E9: Resolvido | F9: =TODAY() -> 46035 | G9: =NETWORKDAYS.INTL(A9,F9,1,'Feriado 2026'!$A$2:$A$14) -> 108 | H9: =IF(G9<=2,"Dentro do SLA","Fora do SLA") -> Fora do SLA
A10: 45882 | B10: WBC-A001235752297 (1458183) | C10: AFS-33136 | D10: 000985870-4 | E10: Resolvido | F10: =TODAY() -> 46035 | G10: =NETWORKDAYS.INTL(A10,F10,1,'Feriado 2026'!$A$2:$A$14) -> 108 | H10: =IF(G10<=2,"Dentro do SLA","Fora do SLA") -> Fora do SLA
A11: 45882 | B11: MGZ-LU-1456070464135473 (1495317) | C11: AFS-33138 | D11: 001010969-4 | E11: Resolvido | F11: =TODAY() -> 46035 | G11: =NETWORKDAYS.INTL(A11,F11,1,'Feriado 2026'!$A$2:$A$14) -> 108 | H11: =IF(G11<=2,"Dentro do SLA","Fora do SLA") -> Fora do SLA
A12: 45882 | B12: MGZ-LU-1458670465210402 (1507168) | C12: AFS-33139 | D12: 001018182-4 | E12: Resolvido | F12: =TODAY() -> 46035 | G12: =NETWORKDAYS.INTL(A12,F12,1,'Feriado 2026'!$A$2:$A$14) -> 108 | H12: =IF(G12<=2,"Dentro do SLA","Fora do SLA") -> Fora do SLA
A13: 45882 | B13: MLP-45230625438 (1495348) | C13: AFS-33141 | D13: 001011408-4 | E13: Em aberto | F13: =TODAY() -> 46035 | G13: =NETWORKDAYS.INTL(A13,F13,1,'Feriado 2026'!$A$2:$A$14) -> 108 | H13: =IF(G13<=2,"Dentro do SLA","Fora do SLA") -> Fora do SLA
... A347: 46034 | B347: 1583011777591-01 (1777591) | C347: AFS-53374 | D347: 001205509-4 | E347: Em aberto | F347: =TODAY() -> 46035 | G347: =NETWORKDAYS.INTL(A347,F347,1,'Feriado 2026'!$A$2:$A$14) -> 2 | H347: =IF(G347<=2,"Dentro do SLA","Fora do SLA") -> Dentro do SLA

Sheet Feriado 2026
A1: Data | B1: Dia da Semana | C1: Feriado
A2: 45658 | B2: quarta-feira | C2: Confraternização Universal
A3: 45719 | B3: segunda-feira | C3: Carnaval
A4: 45720 | B4: terça-feira | C4: Carnaval
A5: 45765 | B5: sexta-feira | C5: Paixão de Cristo
A6: 45768 | B6: segunda-feira | C6: Tiradentes
A7: 45778 | B7: quinta-feira | C7: Dia do Trabalho
A8: 45827 | B8: quinta-feira | C8: Corpus Christi
A9: 45907 | B9: domingo | C9: Independência do Brasil
A10: 45942 | B10: domingo | C10: Nossa Sr.a Aparecida - Padroeira do Brasil
A11: 45963 | B11: domingo | C11: Finados
A12: 45976 | B12: sábado | C12: Proclamação da República
A13: 45981 | B13: quinta-feira | C13: Dia Nacional de Zumbi e da Consciência Negra
A14: 46016 | B14: quinta-feira | C14: Natal
A17: Data | B17: Dia da Semana | C17: Feriado
A18: 46023 | B18: quinta-feira | C18: Confraternização Universal
A19: 46069 | B19: segunda-feira | C19: Carnaval
A20: 46070 | B20: terça-feira | C20: Carnaval
A21: 46115 | B21: sexta-feira | C21: Paixão de Cristo
A22: 46133 | B22: terça-feira | C22: Tiradentes
A23: 46143 | B23: sexta-feira | C23: Dia do Trabalho
A24: 46177 | B24: quinta-feira | C24: Corpus Christi
A25: 46272 | B25: segunda-feira | C25: Independência do Brasil
A26: 46307 | B26: segunda-feira | C26: Nossa Sr.a Aparecida - Padroeira do Brasil
A27: 46328 | B27: segunda-feira | C27: Finados
A28: 46341 | B28: domingo | C28: Proclamação da República
A29: 46346 | B29: sexta-feira | C29: Dia Nacional de Zumbi e da Consciência Negra
A30: 46381 | B30: sexta-feira | C30: Natal

Sheet Dias em Atraso
A3: Contagem de Dias em Atraso | B3: Rótulos de Coluna
A4: Rótulos de Linha | B4: Em aberto | C4: Resolvido | D4: Total Geral
A5: AFS-33135 | C5: 1 | D5: 1
A6: AFS-33136 | C6: 1 | D6: 1
A7: AFS-33138 | C7: 1 | D7: 1
A8: AFS-33139 | C8: 1 | D8: 1
A9: AFS-33141 | B9: 1 | D9: 1
A10: AFS-33145 | B10: 1 | D10: 1
A11: AFS-33224 | C11: 1 | D11: 1
A12: AFS-33228 | C12: 1 | D12: 1
A13: AFS-33233 | C13: 1 | D13: 1
A14: AFS-33235 | C14: 1 | D14: 1
A15: AFS-33241 | C15: 1 | D15: 1
A16: AFS-33244 | B16: 1 | D16: 1
A17: AFS-33247 | B17: 1 | D17: 1
A18: AFS-33254 | C18: 1 | D18: 1
A19: AFS-33386 | C19: 1 | D19: 1
A20: AFS-33448 | C20: 1 | D20: 1
A21: AFS-33455 | C21: 1 | D21: 1
A22: AFS-33463 | C22: 1 | D22: 1
A23: AFS-33466 | B23: 1 | D23: 1
A24: AFS-33471 | B24: 1 | D24: 1
A25: AFS-33478 | B25: 1 | D25: 1
A26: AFS-33480 | B26: 1 | D26: 1
A27: AFS-33484 | B27: 1 | D27: 1
A28: AFS-33696 | B28: 1 | D28: 1
A29: AFS-33701 | B29: 1 | D29: 1
A30: AFS-33702 | B30: 1 | D30: 1
A31: AFS-33706 | B31: 1 | D31: 1
A32: AFS-33712 | B32: 1 | D32: 1
A33: AFS-33713 | B33: 1 | D33: 1
A34: AFS-33718 | B34: 1 | D34: 1
... A40: AFS-34190 | B40: 1 | D40: 1
A41: AFS-34193 | C41: 1 | D41: 1
A42: AFS-34474 | B42: 1 | D42: 1
A43: AFS-34589 | B43: 1 | D43: 1
A44: AFS-34607 | B44: 1 | D44: 1
A45: AFS-34725 | C45: 1 | D45: 1
A46: AFS-34756 | B46: 1 | D46: 1
A47: AFS-34782 | C47: 1 | D47: 1
...
